language: lua
name: Lua
results:
- exit_code: 0
  program: "-- Add two numbers x and y\n-- >>> add(2, 3)\n-- 5\n-- >>> add(5, 7)\n\
    -- 12\nlocal function add(x, y)\n  return x + y\nend\nlu = require('luaunit')\n\
    \nfunction test_humaneval()\nlocal candidate = add\n    lu.assertEquals(candidate(0,\
    \ 1), 1)\n    lu.assertEquals(candidate(1, 0), 1)\n    lu.assertEquals(candidate(2,\
    \ 3), 5)\n    lu.assertEquals(candidate(5, 7), 12)\n    lu.assertEquals(candidate(7,\
    \ 5), 12)\nend\n\nos.exit(lu.LuaUnit.run())"
  status: OK
  stderr: ''
  stdout: '.

    Ran 1 tests in 0.000 seconds, 1 success, 0 failures

    OK

    '
  timestamp: 1659990885
- exit_code: 1
  program: "-- Add two numbers x and y\n-- >>> add(2, 3)\n-- 5\n-- >>> add(5, 7)\n\
    -- 12\nlocal function add(x, y)\n    return x + \nend\nlu = require('luaunit')\n\
    \nfunction test_humaneval()\nlocal candidate = add\n    lu.assertEquals(candidate(0,\
    \ 1), 1)\n    lu.assertEquals(candidate(1, 0), 1)\n    lu.assertEquals(candidate(2,\
    \ 3), 5)\n    lu.assertEquals(candidate(5, 7), 12)\n    lu.assertEquals(candidate(7,\
    \ 5), 12)\nend\n\nos.exit(lu.LuaUnit.run())"
  status: Exception
  stderr: 'lua: /tmp/tmpfr1bcpcw.lua:8: unexpected symbol near ''end''

    '
  stdout: ''
  timestamp: 1659990885
